<?xml version="1.0" ?>
<sdf version="1.6">
    <!-- an invisible conveyor belt -->
    <model name="conveyor_belt">

      <model name="conveyor_belt_fixed">
        <static>true</static>
        <pose>-1.502  0.322 0 0 0 0</pose>
        <link name="link">
          <pose>0 0 0 0 0 0</pose>
	<visual name="belt_mesh">
	    <geometry>
		<mesh>
		    <uri>model://conveyor/model.dae</uri>
		</mesh>
	    </geometry>
	</visual>
        </link>
      </model>

      <model name="conveyor_belt_moving">
        <static>false</static>
        <pose>0 0 0 0 0 0</pose>
        <link name="belt">
          <pose>0 0 0.795 0 0 0</pose>
          <inertial>
            <inertia>
              <ixx>3.8185</ixx>
              <ixy>0</ixy>
              <ixz>0</ixz>
              <iyy>1781.5</iyy>
              <iyz>0</iyz>
              <izz>1784.72</izz>
            </inertia>
            <mass>100</mass>
          </inertial>
          <!--Uncomment for debugging -->
          <!--
          <visual name="belt_visual">
            <geometry>
              <box>
                <size>3.2 0.65461 0.18862</size>
              </box>
            </geometry>
          </visual>
          -->
          <collision name="belt_collision">
            <geometry>
              <box>
                <size>3.2 0.65461 0.18862</size>
              </box>
            </geometry>
            <surface>
              <friction>
                <ode>
                  <mu>1.0</mu>
                  <mu2>1.0</mu2>
                </ode>
                <torsional>
                  <coefficient>1000.0</coefficient>
                  <patch_radius>0.1</patch_radius>
                </torsional>
              </friction>
            </surface>
          </collision>
        </link>
      </model>

      <joint name="belt_joint" type="prismatic">
        <parent>conveyor_belt_fixed::link</parent>
        <child>conveyor_belt_moving::belt</child>
        <axis>
          <xyz>1 0 0</xyz>
          <limit>
            <lower>0</lower>
            <upper>1.0</upper>
          </limit>
        </axis>
      </joint>



      <plugin name="conveyor_belt_plugin" filename="libROSConveyorBeltPlugin.so">
        <robot_namespace>/ariac</robot_namespace>
        <population_rate_modifier_topic>/ariac/population/rate_modifier</population_rate_modifier_topic>
        <link>conveyor_belt::conveyor_belt_moving::belt</link>
        <power>100</power>
      </plugin>
    </model>
</sdf>
